2025-06-20 14:28:43,581 INFO    MainThread:89646 [wandb_setup.py:_flush():70] Current SDK version is 0.19.11
2025-06-20 14:28:43,581 INFO    MainThread:89646 [wandb_setup.py:_flush():70] Configure stats pid to 89646
2025-06-20 14:28:43,581 INFO    MainThread:89646 [wandb_setup.py:_flush():70] Loading settings from /Users/lawrencebinding/.config/wandb/settings
2025-06-20 14:28:43,582 INFO    MainThread:89646 [wandb_setup.py:_flush():70] Loading settings from /Users/lawrencebinding/Desktop/projects/github/LDM-FDG/LDM-FDG/wandb/settings
2025-06-20 14:28:43,582 INFO    MainThread:89646 [wandb_setup.py:_flush():70] Loading settings from environment variables
2025-06-20 14:28:43,582 INFO    MainThread:89646 [wandb_init.py:setup_run_log_directory():724] Logging user logs to /Users/lawrencebinding/Desktop/projects/github/LDM-FDG/LDM-FDG/wandb/run-20250620_142843-aoczfb2k/logs/debug.log
2025-06-20 14:28:43,582 INFO    MainThread:89646 [wandb_init.py:setup_run_log_directory():725] Logging internal logs to /Users/lawrencebinding/Desktop/projects/github/LDM-FDG/LDM-FDG/wandb/run-20250620_142843-aoczfb2k/logs/debug-internal.log
2025-06-20 14:28:43,582 INFO    MainThread:89646 [wandb_init.py:monkeypatch_ipython():643] configuring jupyter hooks <wandb.sdk.wandb_init._WandbInit object at 0x1aa2ef100>
2025-06-20 14:28:43,582 INFO    MainThread:89646 [wandb_init.py:init():852] calling init triggers
2025-06-20 14:28:43,583 INFO    MainThread:89646 [wandb_init.py:init():857] wandb.init called with sweep_config: {}
config: {'learning_rate': 5e-05, 'architecture': 'Autoencoder_KL', 'dataset': 'FDG_2D_slices', 'epochs': 100, 'batch_size': 8, '_wandb': {}}
2025-06-20 14:28:43,583 INFO    MainThread:89646 [wandb_init.py:init():893] starting backend
2025-06-20 14:28:43,583 INFO    MainThread:89646 [wandb_init.py:init():897] sending inform_init request
2025-06-20 14:28:43,629 INFO    MainThread:89646 [backend.py:_multiprocessing_setup():101] multiprocessing start_methods=spawn,fork,forkserver, using: spawn
2025-06-20 14:28:43,629 INFO    MainThread:89646 [wandb_init.py:init():907] backend started and connected
2025-06-20 14:28:43,637 INFO    MainThread:89646 [wandb_run.py:_label_probe_notebook():1376] probe notebook
2025-06-20 14:28:43,638 INFO    MainThread:89646 [wandb_run.py:_label_probe_notebook():1386] Unable to probe notebook: Expecting value: line 1 column 1 (char 0)
2025-06-20 14:28:43,638 INFO    MainThread:89646 [wandb_init.py:init():1005] updated telemetry
2025-06-20 14:28:43,688 INFO    MainThread:89646 [wandb_init.py:init():1029] communicating run to backend with 90.0 second timeout
2025-06-20 14:28:44,246 INFO    MainThread:89646 [wandb_init.py:init():1104] starting run threads in backend
2025-06-20 14:28:44,732 INFO    MainThread:89646 [wandb_run.py:_console_start():2573] atexit reg
2025-06-20 14:28:44,733 INFO    MainThread:89646 [wandb_run.py:_redirect():2421] redirect: wrap_raw
2025-06-20 14:28:44,733 INFO    MainThread:89646 [wandb_run.py:_redirect():2490] Wrapping output streams.
2025-06-20 14:28:44,733 INFO    MainThread:89646 [wandb_run.py:_redirect():2513] Redirects installed.
2025-06-20 14:28:44,736 INFO    MainThread:89646 [wandb_init.py:init():1150] run started, returning control to user process
2025-06-20 14:28:44,779 INFO    MainThread:89646 [wandb_init.py:_post_run_cell_hook():613] [no run ID] resuming backend
2025-06-20 14:28:50,783 INFO    MainThread:89646 [jupyter.py:save_ipynb():401] [no run ID] not saving jupyter notebook
2025-06-20 14:28:50,784 INFO    MainThread:89646 [wandb_init.py:_pre_run_cell_hook():602] [no run ID] pausing backend
2025-06-20 14:28:53,480 WARNING MsgRouterThr:89646 [router.py:message_loop():63] [no run ID] message_loop has been closed
Traceback (most recent call last):
  File "/Users/lawrencebinding/miniconda3/envs/ML/lib/python3.9/site-packages/wandb/sdk/interface/router_sock.py", line 27, in _read_message
    return self._sock_client.read_server_response(timeout=1)
  File "/Users/lawrencebinding/miniconda3/envs/ML/lib/python3.9/site-packages/wandb/sdk/lib/sock_client.py", line 235, in read_server_response
    data = self._read_packet_bytes(timeout=timeout)
  File "/Users/lawrencebinding/miniconda3/envs/ML/lib/python3.9/site-packages/wandb/sdk/lib/sock_client.py", line 220, in _read_packet_bytes
    raise SockClientClosedError
wandb.sdk.lib.sock_client.SockClientClosedError

The above exception was the direct cause of the following exception:

Traceback (most recent call last):
  File "/Users/lawrencebinding/miniconda3/envs/ML/lib/python3.9/site-packages/wandb/sdk/interface/router.py", line 56, in message_loop
    msg = self._read_message()
  File "/Users/lawrencebinding/miniconda3/envs/ML/lib/python3.9/site-packages/wandb/sdk/interface/router_sock.py", line 29, in _read_message
    raise MessageRouterClosedError from e
wandb.sdk.interface.router.MessageRouterClosedError
2025-06-20 14:28:53,482 INFO    MsgRouterThr:89646 [mailbox.py:close():129] [no run ID] Closing mailbox, abandoning 1 handles.
2025-06-20 14:28:55,459 INFO    MainThread:89646 [wandb_init.py:_post_run_cell_hook():613] [no run ID] resuming backend
2025-06-20 14:29:27,576 INFO    MainThread:89646 [jupyter.py:save_ipynb():401] [no run ID] not saving jupyter notebook
2025-06-20 14:29:27,577 INFO    MainThread:89646 [wandb_init.py:_pre_run_cell_hook():602] [no run ID] pausing backend
2025-06-20 14:29:27,578 ERROR   MainThread:89646 [redirect.py:_on_write():664] [no run ID] error in stdout callback
Traceback (most recent call last):
  File "/Users/lawrencebinding/miniconda3/envs/ML/lib/python3.9/site-packages/IPython/core/events.py", line 82, in trigger
    func(*args, **kwargs)
  File "/Users/lawrencebinding/miniconda3/envs/ML/lib/python3.9/site-packages/wandb/sdk/wandb_init.py", line 603, in _pre_run_cell_hook
    self.backend.interface.publish_pause()
  File "/Users/lawrencebinding/miniconda3/envs/ML/lib/python3.9/site-packages/wandb/sdk/interface/interface.py", line 770, in publish_pause
    self._publish_pause(pause)
  File "/Users/lawrencebinding/miniconda3/envs/ML/lib/python3.9/site-packages/wandb/sdk/interface/interface_shared.py", line 289, in _publish_pause
    self._publish(rec)
  File "/Users/lawrencebinding/miniconda3/envs/ML/lib/python3.9/site-packages/wandb/sdk/interface/interface_sock.py", line 39, in _publish
    self._sock_client.send_record_publish(record)
  File "/Users/lawrencebinding/miniconda3/envs/ML/lib/python3.9/site-packages/wandb/sdk/lib/sock_client.py", line 174, in send_record_publish
    self.send_server_request(server_req)
  File "/Users/lawrencebinding/miniconda3/envs/ML/lib/python3.9/site-packages/wandb/sdk/lib/sock_client.py", line 154, in send_server_request
    self._send_message(msg)
  File "/Users/lawrencebinding/miniconda3/envs/ML/lib/python3.9/site-packages/wandb/sdk/lib/sock_client.py", line 151, in _send_message
    self._sendall_with_error_handle(header + data)
  File "/Users/lawrencebinding/miniconda3/envs/ML/lib/python3.9/site-packages/wandb/sdk/lib/sock_client.py", line 130, in _sendall_with_error_handle
    sent = self._sock.send(data)
BrokenPipeError: [Errno 32] Broken pipe

During handling of the above exception, another exception occurred:

Traceback (most recent call last):
  File "/Users/lawrencebinding/miniconda3/envs/ML/lib/python3.9/site-packages/wandb/sdk/lib/redirect.py", line 662, in _on_write
    cb(written_data)
  File "/Users/lawrencebinding/miniconda3/envs/ML/lib/python3.9/site-packages/wandb/sdk/wandb_run.py", line 2494, in <lambda>
    lambda data: self._console_raw_callback("stdout", data),
  File "/Users/lawrencebinding/miniconda3/envs/ML/lib/python3.9/site-packages/wandb/sdk/wandb_run.py", line 406, in wrapper
    return func(self, *args, **kwargs)
  File "/Users/lawrencebinding/miniconda3/envs/ML/lib/python3.9/site-packages/wandb/sdk/wandb_run.py", line 464, in wrapper_fn
    return func(self, *args, **kwargs)
  File "/Users/lawrencebinding/miniconda3/envs/ML/lib/python3.9/site-packages/wandb/sdk/wandb_run.py", line 1639, in _console_raw_callback
    self._backend.interface.publish_output_raw(name, data)
  File "/Users/lawrencebinding/miniconda3/envs/ML/lib/python3.9/site-packages/wandb/sdk/interface/interface.py", line 762, in publish_output_raw
    self._publish_output_raw(o)
  File "/Users/lawrencebinding/miniconda3/envs/ML/lib/python3.9/site-packages/wandb/sdk/interface/interface_shared.py", line 38, in _publish_output_raw
    self._publish(rec)
  File "/Users/lawrencebinding/miniconda3/envs/ML/lib/python3.9/site-packages/wandb/sdk/interface/interface_sock.py", line 39, in _publish
    self._sock_client.send_record_publish(record)
  File "/Users/lawrencebinding/miniconda3/envs/ML/lib/python3.9/site-packages/wandb/sdk/lib/sock_client.py", line 174, in send_record_publish
    self.send_server_request(server_req)
  File "/Users/lawrencebinding/miniconda3/envs/ML/lib/python3.9/site-packages/wandb/sdk/lib/sock_client.py", line 154, in send_server_request
    self._send_message(msg)
  File "/Users/lawrencebinding/miniconda3/envs/ML/lib/python3.9/site-packages/wandb/sdk/lib/sock_client.py", line 151, in _send_message
    self._sendall_with_error_handle(header + data)
  File "/Users/lawrencebinding/miniconda3/envs/ML/lib/python3.9/site-packages/wandb/sdk/lib/sock_client.py", line 130, in _sendall_with_error_handle
    sent = self._sock.send(data)
BrokenPipeError: [Errno 32] Broken pipe
2025-06-20 14:29:27,585 ERROR   MainThread:89646 [redirect.py:_on_write():664] [no run ID] error in stdout callback
Traceback (most recent call last):
  File "/Users/lawrencebinding/miniconda3/envs/ML/lib/python3.9/site-packages/IPython/core/events.py", line 82, in trigger
    func(*args, **kwargs)
  File "/Users/lawrencebinding/miniconda3/envs/ML/lib/python3.9/site-packages/wandb/sdk/wandb_init.py", line 603, in _pre_run_cell_hook
    self.backend.interface.publish_pause()
  File "/Users/lawrencebinding/miniconda3/envs/ML/lib/python3.9/site-packages/wandb/sdk/interface/interface.py", line 770, in publish_pause
    self._publish_pause(pause)
  File "/Users/lawrencebinding/miniconda3/envs/ML/lib/python3.9/site-packages/wandb/sdk/interface/interface_shared.py", line 289, in _publish_pause
    self._publish(rec)
  File "/Users/lawrencebinding/miniconda3/envs/ML/lib/python3.9/site-packages/wandb/sdk/interface/interface_sock.py", line 39, in _publish
    self._sock_client.send_record_publish(record)
  File "/Users/lawrencebinding/miniconda3/envs/ML/lib/python3.9/site-packages/wandb/sdk/lib/sock_client.py", line 174, in send_record_publish
    self.send_server_request(server_req)
  File "/Users/lawrencebinding/miniconda3/envs/ML/lib/python3.9/site-packages/wandb/sdk/lib/sock_client.py", line 154, in send_server_request
    self._send_message(msg)
  File "/Users/lawrencebinding/miniconda3/envs/ML/lib/python3.9/site-packages/wandb/sdk/lib/sock_client.py", line 151, in _send_message
    self._sendall_with_error_handle(header + data)
  File "/Users/lawrencebinding/miniconda3/envs/ML/lib/python3.9/site-packages/wandb/sdk/lib/sock_client.py", line 130, in _sendall_with_error_handle
    sent = self._sock.send(data)
BrokenPipeError: [Errno 32] Broken pipe

During handling of the above exception, another exception occurred:

Traceback (most recent call last):
  File "/Users/lawrencebinding/miniconda3/envs/ML/lib/python3.9/site-packages/wandb/sdk/lib/redirect.py", line 662, in _on_write
    cb(written_data)
  File "/Users/lawrencebinding/miniconda3/envs/ML/lib/python3.9/site-packages/wandb/sdk/wandb_run.py", line 2494, in <lambda>
    lambda data: self._console_raw_callback("stdout", data),
  File "/Users/lawrencebinding/miniconda3/envs/ML/lib/python3.9/site-packages/wandb/sdk/wandb_run.py", line 406, in wrapper
    return func(self, *args, **kwargs)
  File "/Users/lawrencebinding/miniconda3/envs/ML/lib/python3.9/site-packages/wandb/sdk/wandb_run.py", line 464, in wrapper_fn
    return func(self, *args, **kwargs)
  File "/Users/lawrencebinding/miniconda3/envs/ML/lib/python3.9/site-packages/wandb/sdk/wandb_run.py", line 1639, in _console_raw_callback
    self._backend.interface.publish_output_raw(name, data)
  File "/Users/lawrencebinding/miniconda3/envs/ML/lib/python3.9/site-packages/wandb/sdk/interface/interface.py", line 762, in publish_output_raw
    self._publish_output_raw(o)
  File "/Users/lawrencebinding/miniconda3/envs/ML/lib/python3.9/site-packages/wandb/sdk/interface/interface_shared.py", line 38, in _publish_output_raw
    self._publish(rec)
  File "/Users/lawrencebinding/miniconda3/envs/ML/lib/python3.9/site-packages/wandb/sdk/interface/interface_sock.py", line 39, in _publish
    self._sock_client.send_record_publish(record)
  File "/Users/lawrencebinding/miniconda3/envs/ML/lib/python3.9/site-packages/wandb/sdk/lib/sock_client.py", line 174, in send_record_publish
    self.send_server_request(server_req)
  File "/Users/lawrencebinding/miniconda3/envs/ML/lib/python3.9/site-packages/wandb/sdk/lib/sock_client.py", line 154, in send_server_request
    self._send_message(msg)
  File "/Users/lawrencebinding/miniconda3/envs/ML/lib/python3.9/site-packages/wandb/sdk/lib/sock_client.py", line 151, in _send_message
    self._sendall_with_error_handle(header + data)
  File "/Users/lawrencebinding/miniconda3/envs/ML/lib/python3.9/site-packages/wandb/sdk/lib/sock_client.py", line 130, in _sendall_with_error_handle
    sent = self._sock.send(data)
BrokenPipeError: [Errno 32] Broken pipe
2025-06-20 14:29:28,097 INFO    MainThread:89646 [wandb_init.py:_post_run_cell_hook():613] [no run ID] resuming backend
2025-06-20 14:29:28,098 ERROR   MainThread:89646 [redirect.py:_on_write():664] [no run ID] error in stdout callback
Traceback (most recent call last):
  File "/Users/lawrencebinding/miniconda3/envs/ML/lib/python3.9/site-packages/IPython/core/events.py", line 82, in trigger
    func(*args, **kwargs)
  File "/Users/lawrencebinding/miniconda3/envs/ML/lib/python3.9/site-packages/wandb/sdk/wandb_init.py", line 614, in _post_run_cell_hook
    self.backend.interface.publish_resume()
  File "/Users/lawrencebinding/miniconda3/envs/ML/lib/python3.9/site-packages/wandb/sdk/interface/interface.py", line 778, in publish_resume
    self._publish_resume(resume)
  File "/Users/lawrencebinding/miniconda3/envs/ML/lib/python3.9/site-packages/wandb/sdk/interface/interface_shared.py", line 293, in _publish_resume
    self._publish(rec)
  File "/Users/lawrencebinding/miniconda3/envs/ML/lib/python3.9/site-packages/wandb/sdk/interface/interface_sock.py", line 39, in _publish
    self._sock_client.send_record_publish(record)
  File "/Users/lawrencebinding/miniconda3/envs/ML/lib/python3.9/site-packages/wandb/sdk/lib/sock_client.py", line 174, in send_record_publish
    self.send_server_request(server_req)
  File "/Users/lawrencebinding/miniconda3/envs/ML/lib/python3.9/site-packages/wandb/sdk/lib/sock_client.py", line 154, in send_server_request
    self._send_message(msg)
  File "/Users/lawrencebinding/miniconda3/envs/ML/lib/python3.9/site-packages/wandb/sdk/lib/sock_client.py", line 151, in _send_message
    self._sendall_with_error_handle(header + data)
  File "/Users/lawrencebinding/miniconda3/envs/ML/lib/python3.9/site-packages/wandb/sdk/lib/sock_client.py", line 130, in _sendall_with_error_handle
    sent = self._sock.send(data)
BrokenPipeError: [Errno 32] Broken pipe

During handling of the above exception, another exception occurred:

Traceback (most recent call last):
  File "/Users/lawrencebinding/miniconda3/envs/ML/lib/python3.9/site-packages/wandb/sdk/lib/redirect.py", line 662, in _on_write
    cb(written_data)
  File "/Users/lawrencebinding/miniconda3/envs/ML/lib/python3.9/site-packages/wandb/sdk/wandb_run.py", line 2494, in <lambda>
    lambda data: self._console_raw_callback("stdout", data),
  File "/Users/lawrencebinding/miniconda3/envs/ML/lib/python3.9/site-packages/wandb/sdk/wandb_run.py", line 406, in wrapper
    return func(self, *args, **kwargs)
  File "/Users/lawrencebinding/miniconda3/envs/ML/lib/python3.9/site-packages/wandb/sdk/wandb_run.py", line 464, in wrapper_fn
    return func(self, *args, **kwargs)
  File "/Users/lawrencebinding/miniconda3/envs/ML/lib/python3.9/site-packages/wandb/sdk/wandb_run.py", line 1639, in _console_raw_callback
    self._backend.interface.publish_output_raw(name, data)
  File "/Users/lawrencebinding/miniconda3/envs/ML/lib/python3.9/site-packages/wandb/sdk/interface/interface.py", line 762, in publish_output_raw
    self._publish_output_raw(o)
  File "/Users/lawrencebinding/miniconda3/envs/ML/lib/python3.9/site-packages/wandb/sdk/interface/interface_shared.py", line 38, in _publish_output_raw
    self._publish(rec)
  File "/Users/lawrencebinding/miniconda3/envs/ML/lib/python3.9/site-packages/wandb/sdk/interface/interface_sock.py", line 39, in _publish
    self._sock_client.send_record_publish(record)
  File "/Users/lawrencebinding/miniconda3/envs/ML/lib/python3.9/site-packages/wandb/sdk/lib/sock_client.py", line 174, in send_record_publish
    self.send_server_request(server_req)
  File "/Users/lawrencebinding/miniconda3/envs/ML/lib/python3.9/site-packages/wandb/sdk/lib/sock_client.py", line 154, in send_server_request
    self._send_message(msg)
  File "/Users/lawrencebinding/miniconda3/envs/ML/lib/python3.9/site-packages/wandb/sdk/lib/sock_client.py", line 151, in _send_message
    self._sendall_with_error_handle(header + data)
  File "/Users/lawrencebinding/miniconda3/envs/ML/lib/python3.9/site-packages/wandb/sdk/lib/sock_client.py", line 130, in _sendall_with_error_handle
    sent = self._sock.send(data)
BrokenPipeError: [Errno 32] Broken pipe
2025-06-20 14:29:28,099 ERROR   MainThread:89646 [redirect.py:_on_write():664] [no run ID] error in stdout callback
Traceback (most recent call last):
  File "/Users/lawrencebinding/miniconda3/envs/ML/lib/python3.9/site-packages/IPython/core/events.py", line 82, in trigger
    func(*args, **kwargs)
  File "/Users/lawrencebinding/miniconda3/envs/ML/lib/python3.9/site-packages/wandb/sdk/wandb_init.py", line 614, in _post_run_cell_hook
    self.backend.interface.publish_resume()
  File "/Users/lawrencebinding/miniconda3/envs/ML/lib/python3.9/site-packages/wandb/sdk/interface/interface.py", line 778, in publish_resume
    self._publish_resume(resume)
  File "/Users/lawrencebinding/miniconda3/envs/ML/lib/python3.9/site-packages/wandb/sdk/interface/interface_shared.py", line 293, in _publish_resume
    self._publish(rec)
  File "/Users/lawrencebinding/miniconda3/envs/ML/lib/python3.9/site-packages/wandb/sdk/interface/interface_sock.py", line 39, in _publish
    self._sock_client.send_record_publish(record)
  File "/Users/lawrencebinding/miniconda3/envs/ML/lib/python3.9/site-packages/wandb/sdk/lib/sock_client.py", line 174, in send_record_publish
    self.send_server_request(server_req)
  File "/Users/lawrencebinding/miniconda3/envs/ML/lib/python3.9/site-packages/wandb/sdk/lib/sock_client.py", line 154, in send_server_request
    self._send_message(msg)
  File "/Users/lawrencebinding/miniconda3/envs/ML/lib/python3.9/site-packages/wandb/sdk/lib/sock_client.py", line 151, in _send_message
    self._sendall_with_error_handle(header + data)
  File "/Users/lawrencebinding/miniconda3/envs/ML/lib/python3.9/site-packages/wandb/sdk/lib/sock_client.py", line 130, in _sendall_with_error_handle
    sent = self._sock.send(data)
BrokenPipeError: [Errno 32] Broken pipe

During handling of the above exception, another exception occurred:

Traceback (most recent call last):
  File "/Users/lawrencebinding/miniconda3/envs/ML/lib/python3.9/site-packages/wandb/sdk/lib/redirect.py", line 662, in _on_write
    cb(written_data)
  File "/Users/lawrencebinding/miniconda3/envs/ML/lib/python3.9/site-packages/wandb/sdk/wandb_run.py", line 2494, in <lambda>
    lambda data: self._console_raw_callback("stdout", data),
  File "/Users/lawrencebinding/miniconda3/envs/ML/lib/python3.9/site-packages/wandb/sdk/wandb_run.py", line 406, in wrapper
    return func(self, *args, **kwargs)
  File "/Users/lawrencebinding/miniconda3/envs/ML/lib/python3.9/site-packages/wandb/sdk/wandb_run.py", line 464, in wrapper_fn
    return func(self, *args, **kwargs)
  File "/Users/lawrencebinding/miniconda3/envs/ML/lib/python3.9/site-packages/wandb/sdk/wandb_run.py", line 1639, in _console_raw_callback
    self._backend.interface.publish_output_raw(name, data)
  File "/Users/lawrencebinding/miniconda3/envs/ML/lib/python3.9/site-packages/wandb/sdk/interface/interface.py", line 762, in publish_output_raw
    self._publish_output_raw(o)
  File "/Users/lawrencebinding/miniconda3/envs/ML/lib/python3.9/site-packages/wandb/sdk/interface/interface_shared.py", line 38, in _publish_output_raw
    self._publish(rec)
  File "/Users/lawrencebinding/miniconda3/envs/ML/lib/python3.9/site-packages/wandb/sdk/interface/interface_sock.py", line 39, in _publish
    self._sock_client.send_record_publish(record)
  File "/Users/lawrencebinding/miniconda3/envs/ML/lib/python3.9/site-packages/wandb/sdk/lib/sock_client.py", line 174, in send_record_publish
    self.send_server_request(server_req)
  File "/Users/lawrencebinding/miniconda3/envs/ML/lib/python3.9/site-packages/wandb/sdk/lib/sock_client.py", line 154, in send_server_request
    self._send_message(msg)
  File "/Users/lawrencebinding/miniconda3/envs/ML/lib/python3.9/site-packages/wandb/sdk/lib/sock_client.py", line 151, in _send_message
    self._sendall_with_error_handle(header + data)
  File "/Users/lawrencebinding/miniconda3/envs/ML/lib/python3.9/site-packages/wandb/sdk/lib/sock_client.py", line 130, in _sendall_with_error_handle
    sent = self._sock.send(data)
BrokenPipeError: [Errno 32] Broken pipe
2025-06-20 14:29:43,434 INFO    MainThread:89646 [jupyter.py:save_ipynb():401] [no run ID] not saving jupyter notebook
2025-06-20 14:29:43,434 INFO    MainThread:89646 [wandb_init.py:_pre_run_cell_hook():602] [no run ID] pausing backend
2025-06-20 14:29:43,435 ERROR   MainThread:89646 [redirect.py:_on_write():664] [no run ID] error in stdout callback
Traceback (most recent call last):
  File "/Users/lawrencebinding/miniconda3/envs/ML/lib/python3.9/site-packages/IPython/core/events.py", line 82, in trigger
    func(*args, **kwargs)
  File "/Users/lawrencebinding/miniconda3/envs/ML/lib/python3.9/site-packages/wandb/sdk/wandb_init.py", line 603, in _pre_run_cell_hook
    self.backend.interface.publish_pause()
  File "/Users/lawrencebinding/miniconda3/envs/ML/lib/python3.9/site-packages/wandb/sdk/interface/interface.py", line 770, in publish_pause
    self._publish_pause(pause)
  File "/Users/lawrencebinding/miniconda3/envs/ML/lib/python3.9/site-packages/wandb/sdk/interface/interface_shared.py", line 289, in _publish_pause
    self._publish(rec)
  File "/Users/lawrencebinding/miniconda3/envs/ML/lib/python3.9/site-packages/wandb/sdk/interface/interface_sock.py", line 39, in _publish
    self._sock_client.send_record_publish(record)
  File "/Users/lawrencebinding/miniconda3/envs/ML/lib/python3.9/site-packages/wandb/sdk/lib/sock_client.py", line 174, in send_record_publish
    self.send_server_request(server_req)
  File "/Users/lawrencebinding/miniconda3/envs/ML/lib/python3.9/site-packages/wandb/sdk/lib/sock_client.py", line 154, in send_server_request
    self._send_message(msg)
  File "/Users/lawrencebinding/miniconda3/envs/ML/lib/python3.9/site-packages/wandb/sdk/lib/sock_client.py", line 151, in _send_message
    self._sendall_with_error_handle(header + data)
  File "/Users/lawrencebinding/miniconda3/envs/ML/lib/python3.9/site-packages/wandb/sdk/lib/sock_client.py", line 130, in _sendall_with_error_handle
    sent = self._sock.send(data)
BrokenPipeError: [Errno 32] Broken pipe

During handling of the above exception, another exception occurred:

Traceback (most recent call last):
  File "/Users/lawrencebinding/miniconda3/envs/ML/lib/python3.9/site-packages/wandb/sdk/lib/redirect.py", line 662, in _on_write
    cb(written_data)
  File "/Users/lawrencebinding/miniconda3/envs/ML/lib/python3.9/site-packages/wandb/sdk/wandb_run.py", line 2494, in <lambda>
    lambda data: self._console_raw_callback("stdout", data),
  File "/Users/lawrencebinding/miniconda3/envs/ML/lib/python3.9/site-packages/wandb/sdk/wandb_run.py", line 406, in wrapper
    return func(self, *args, **kwargs)
  File "/Users/lawrencebinding/miniconda3/envs/ML/lib/python3.9/site-packages/wandb/sdk/wandb_run.py", line 464, in wrapper_fn
    return func(self, *args, **kwargs)
  File "/Users/lawrencebinding/miniconda3/envs/ML/lib/python3.9/site-packages/wandb/sdk/wandb_run.py", line 1639, in _console_raw_callback
    self._backend.interface.publish_output_raw(name, data)
  File "/Users/lawrencebinding/miniconda3/envs/ML/lib/python3.9/site-packages/wandb/sdk/interface/interface.py", line 762, in publish_output_raw
    self._publish_output_raw(o)
  File "/Users/lawrencebinding/miniconda3/envs/ML/lib/python3.9/site-packages/wandb/sdk/interface/interface_shared.py", line 38, in _publish_output_raw
    self._publish(rec)
  File "/Users/lawrencebinding/miniconda3/envs/ML/lib/python3.9/site-packages/wandb/sdk/interface/interface_sock.py", line 39, in _publish
    self._sock_client.send_record_publish(record)
  File "/Users/lawrencebinding/miniconda3/envs/ML/lib/python3.9/site-packages/wandb/sdk/lib/sock_client.py", line 174, in send_record_publish
    self.send_server_request(server_req)
  File "/Users/lawrencebinding/miniconda3/envs/ML/lib/python3.9/site-packages/wandb/sdk/lib/sock_client.py", line 154, in send_server_request
    self._send_message(msg)
  File "/Users/lawrencebinding/miniconda3/envs/ML/lib/python3.9/site-packages/wandb/sdk/lib/sock_client.py", line 151, in _send_message
    self._sendall_with_error_handle(header + data)
  File "/Users/lawrencebinding/miniconda3/envs/ML/lib/python3.9/site-packages/wandb/sdk/lib/sock_client.py", line 130, in _sendall_with_error_handle
    sent = self._sock.send(data)
BrokenPipeError: [Errno 32] Broken pipe
2025-06-20 14:29:43,436 ERROR   MainThread:89646 [redirect.py:_on_write():664] [no run ID] error in stdout callback
Traceback (most recent call last):
  File "/Users/lawrencebinding/miniconda3/envs/ML/lib/python3.9/site-packages/IPython/core/events.py", line 82, in trigger
    func(*args, **kwargs)
  File "/Users/lawrencebinding/miniconda3/envs/ML/lib/python3.9/site-packages/wandb/sdk/wandb_init.py", line 603, in _pre_run_cell_hook
    self.backend.interface.publish_pause()
  File "/Users/lawrencebinding/miniconda3/envs/ML/lib/python3.9/site-packages/wandb/sdk/interface/interface.py", line 770, in publish_pause
    self._publish_pause(pause)
  File "/Users/lawrencebinding/miniconda3/envs/ML/lib/python3.9/site-packages/wandb/sdk/interface/interface_shared.py", line 289, in _publish_pause
    self._publish(rec)
  File "/Users/lawrencebinding/miniconda3/envs/ML/lib/python3.9/site-packages/wandb/sdk/interface/interface_sock.py", line 39, in _publish
    self._sock_client.send_record_publish(record)
  File "/Users/lawrencebinding/miniconda3/envs/ML/lib/python3.9/site-packages/wandb/sdk/lib/sock_client.py", line 174, in send_record_publish
    self.send_server_request(server_req)
  File "/Users/lawrencebinding/miniconda3/envs/ML/lib/python3.9/site-packages/wandb/sdk/lib/sock_client.py", line 154, in send_server_request
    self._send_message(msg)
  File "/Users/lawrencebinding/miniconda3/envs/ML/lib/python3.9/site-packages/wandb/sdk/lib/sock_client.py", line 151, in _send_message
    self._sendall_with_error_handle(header + data)
  File "/Users/lawrencebinding/miniconda3/envs/ML/lib/python3.9/site-packages/wandb/sdk/lib/sock_client.py", line 130, in _sendall_with_error_handle
    sent = self._sock.send(data)
BrokenPipeError: [Errno 32] Broken pipe

During handling of the above exception, another exception occurred:

Traceback (most recent call last):
  File "/Users/lawrencebinding/miniconda3/envs/ML/lib/python3.9/site-packages/wandb/sdk/lib/redirect.py", line 662, in _on_write
    cb(written_data)
  File "/Users/lawrencebinding/miniconda3/envs/ML/lib/python3.9/site-packages/wandb/sdk/wandb_run.py", line 2494, in <lambda>
    lambda data: self._console_raw_callback("stdout", data),
  File "/Users/lawrencebinding/miniconda3/envs/ML/lib/python3.9/site-packages/wandb/sdk/wandb_run.py", line 406, in wrapper
    return func(self, *args, **kwargs)
  File "/Users/lawrencebinding/miniconda3/envs/ML/lib/python3.9/site-packages/wandb/sdk/wandb_run.py", line 464, in wrapper_fn
    return func(self, *args, **kwargs)
  File "/Users/lawrencebinding/miniconda3/envs/ML/lib/python3.9/site-packages/wandb/sdk/wandb_run.py", line 1639, in _console_raw_callback
    self._backend.interface.publish_output_raw(name, data)
  File "/Users/lawrencebinding/miniconda3/envs/ML/lib/python3.9/site-packages/wandb/sdk/interface/interface.py", line 762, in publish_output_raw
    self._publish_output_raw(o)
  File "/Users/lawrencebinding/miniconda3/envs/ML/lib/python3.9/site-packages/wandb/sdk/interface/interface_shared.py", line 38, in _publish_output_raw
    self._publish(rec)
  File "/Users/lawrencebinding/miniconda3/envs/ML/lib/python3.9/site-packages/wandb/sdk/interface/interface_sock.py", line 39, in _publish
    self._sock_client.send_record_publish(record)
  File "/Users/lawrencebinding/miniconda3/envs/ML/lib/python3.9/site-packages/wandb/sdk/lib/sock_client.py", line 174, in send_record_publish
    self.send_server_request(server_req)
  File "/Users/lawrencebinding/miniconda3/envs/ML/lib/python3.9/site-packages/wandb/sdk/lib/sock_client.py", line 154, in send_server_request
    self._send_message(msg)
  File "/Users/lawrencebinding/miniconda3/envs/ML/lib/python3.9/site-packages/wandb/sdk/lib/sock_client.py", line 151, in _send_message
    self._sendall_with_error_handle(header + data)
  File "/Users/lawrencebinding/miniconda3/envs/ML/lib/python3.9/site-packages/wandb/sdk/lib/sock_client.py", line 130, in _sendall_with_error_handle
    sent = self._sock.send(data)
BrokenPipeError: [Errno 32] Broken pipe
2025-06-20 14:29:43,497 INFO    MainThread:89646 [wandb_init.py:_post_run_cell_hook():613] [no run ID] resuming backend
2025-06-20 14:29:43,498 ERROR   MainThread:89646 [redirect.py:_on_write():664] [no run ID] error in stdout callback
Traceback (most recent call last):
  File "/Users/lawrencebinding/miniconda3/envs/ML/lib/python3.9/site-packages/IPython/core/events.py", line 82, in trigger
    func(*args, **kwargs)
  File "/Users/lawrencebinding/miniconda3/envs/ML/lib/python3.9/site-packages/wandb/sdk/wandb_init.py", line 614, in _post_run_cell_hook
    self.backend.interface.publish_resume()
  File "/Users/lawrencebinding/miniconda3/envs/ML/lib/python3.9/site-packages/wandb/sdk/interface/interface.py", line 778, in publish_resume
    self._publish_resume(resume)
  File "/Users/lawrencebinding/miniconda3/envs/ML/lib/python3.9/site-packages/wandb/sdk/interface/interface_shared.py", line 293, in _publish_resume
    self._publish(rec)
  File "/Users/lawrencebinding/miniconda3/envs/ML/lib/python3.9/site-packages/wandb/sdk/interface/interface_sock.py", line 39, in _publish
    self._sock_client.send_record_publish(record)
  File "/Users/lawrencebinding/miniconda3/envs/ML/lib/python3.9/site-packages/wandb/sdk/lib/sock_client.py", line 174, in send_record_publish
    self.send_server_request(server_req)
  File "/Users/lawrencebinding/miniconda3/envs/ML/lib/python3.9/site-packages/wandb/sdk/lib/sock_client.py", line 154, in send_server_request
    self._send_message(msg)
  File "/Users/lawrencebinding/miniconda3/envs/ML/lib/python3.9/site-packages/wandb/sdk/lib/sock_client.py", line 151, in _send_message
    self._sendall_with_error_handle(header + data)
  File "/Users/lawrencebinding/miniconda3/envs/ML/lib/python3.9/site-packages/wandb/sdk/lib/sock_client.py", line 130, in _sendall_with_error_handle
    sent = self._sock.send(data)
BrokenPipeError: [Errno 32] Broken pipe

During handling of the above exception, another exception occurred:

Traceback (most recent call last):
  File "/Users/lawrencebinding/miniconda3/envs/ML/lib/python3.9/site-packages/wandb/sdk/lib/redirect.py", line 662, in _on_write
    cb(written_data)
  File "/Users/lawrencebinding/miniconda3/envs/ML/lib/python3.9/site-packages/wandb/sdk/wandb_run.py", line 2494, in <lambda>
    lambda data: self._console_raw_callback("stdout", data),
  File "/Users/lawrencebinding/miniconda3/envs/ML/lib/python3.9/site-packages/wandb/sdk/wandb_run.py", line 406, in wrapper
    return func(self, *args, **kwargs)
  File "/Users/lawrencebinding/miniconda3/envs/ML/lib/python3.9/site-packages/wandb/sdk/wandb_run.py", line 464, in wrapper_fn
    return func(self, *args, **kwargs)
  File "/Users/lawrencebinding/miniconda3/envs/ML/lib/python3.9/site-packages/wandb/sdk/wandb_run.py", line 1639, in _console_raw_callback
    self._backend.interface.publish_output_raw(name, data)
  File "/Users/lawrencebinding/miniconda3/envs/ML/lib/python3.9/site-packages/wandb/sdk/interface/interface.py", line 762, in publish_output_raw
    self._publish_output_raw(o)
  File "/Users/lawrencebinding/miniconda3/envs/ML/lib/python3.9/site-packages/wandb/sdk/interface/interface_shared.py", line 38, in _publish_output_raw
    self._publish(rec)
  File "/Users/lawrencebinding/miniconda3/envs/ML/lib/python3.9/site-packages/wandb/sdk/interface/interface_sock.py", line 39, in _publish
    self._sock_client.send_record_publish(record)
  File "/Users/lawrencebinding/miniconda3/envs/ML/lib/python3.9/site-packages/wandb/sdk/lib/sock_client.py", line 174, in send_record_publish
    self.send_server_request(server_req)
  File "/Users/lawrencebinding/miniconda3/envs/ML/lib/python3.9/site-packages/wandb/sdk/lib/sock_client.py", line 154, in send_server_request
    self._send_message(msg)
  File "/Users/lawrencebinding/miniconda3/envs/ML/lib/python3.9/site-packages/wandb/sdk/lib/sock_client.py", line 151, in _send_message
    self._sendall_with_error_handle(header + data)
  File "/Users/lawrencebinding/miniconda3/envs/ML/lib/python3.9/site-packages/wandb/sdk/lib/sock_client.py", line 130, in _sendall_with_error_handle
    sent = self._sock.send(data)
BrokenPipeError: [Errno 32] Broken pipe
2025-06-20 14:29:43,499 ERROR   MainThread:89646 [redirect.py:_on_write():664] [no run ID] error in stdout callback
Traceback (most recent call last):
  File "/Users/lawrencebinding/miniconda3/envs/ML/lib/python3.9/site-packages/IPython/core/events.py", line 82, in trigger
    func(*args, **kwargs)
  File "/Users/lawrencebinding/miniconda3/envs/ML/lib/python3.9/site-packages/wandb/sdk/wandb_init.py", line 614, in _post_run_cell_hook
    self.backend.interface.publish_resume()
  File "/Users/lawrencebinding/miniconda3/envs/ML/lib/python3.9/site-packages/wandb/sdk/interface/interface.py", line 778, in publish_resume
    self._publish_resume(resume)
  File "/Users/lawrencebinding/miniconda3/envs/ML/lib/python3.9/site-packages/wandb/sdk/interface/interface_shared.py", line 293, in _publish_resume
    self._publish(rec)
  File "/Users/lawrencebinding/miniconda3/envs/ML/lib/python3.9/site-packages/wandb/sdk/interface/interface_sock.py", line 39, in _publish
    self._sock_client.send_record_publish(record)
  File "/Users/lawrencebinding/miniconda3/envs/ML/lib/python3.9/site-packages/wandb/sdk/lib/sock_client.py", line 174, in send_record_publish
    self.send_server_request(server_req)
  File "/Users/lawrencebinding/miniconda3/envs/ML/lib/python3.9/site-packages/wandb/sdk/lib/sock_client.py", line 154, in send_server_request
    self._send_message(msg)
  File "/Users/lawrencebinding/miniconda3/envs/ML/lib/python3.9/site-packages/wandb/sdk/lib/sock_client.py", line 151, in _send_message
    self._sendall_with_error_handle(header + data)
  File "/Users/lawrencebinding/miniconda3/envs/ML/lib/python3.9/site-packages/wandb/sdk/lib/sock_client.py", line 130, in _sendall_with_error_handle
    sent = self._sock.send(data)
BrokenPipeError: [Errno 32] Broken pipe

During handling of the above exception, another exception occurred:

Traceback (most recent call last):
  File "/Users/lawrencebinding/miniconda3/envs/ML/lib/python3.9/site-packages/wandb/sdk/lib/redirect.py", line 662, in _on_write
    cb(written_data)
  File "/Users/lawrencebinding/miniconda3/envs/ML/lib/python3.9/site-packages/wandb/sdk/wandb_run.py", line 2494, in <lambda>
    lambda data: self._console_raw_callback("stdout", data),
  File "/Users/lawrencebinding/miniconda3/envs/ML/lib/python3.9/site-packages/wandb/sdk/wandb_run.py", line 406, in wrapper
    return func(self, *args, **kwargs)
  File "/Users/lawrencebinding/miniconda3/envs/ML/lib/python3.9/site-packages/wandb/sdk/wandb_run.py", line 464, in wrapper_fn
    return func(self, *args, **kwargs)
  File "/Users/lawrencebinding/miniconda3/envs/ML/lib/python3.9/site-packages/wandb/sdk/wandb_run.py", line 1639, in _console_raw_callback
    self._backend.interface.publish_output_raw(name, data)
  File "/Users/lawrencebinding/miniconda3/envs/ML/lib/python3.9/site-packages/wandb/sdk/interface/interface.py", line 762, in publish_output_raw
    self._publish_output_raw(o)
  File "/Users/lawrencebinding/miniconda3/envs/ML/lib/python3.9/site-packages/wandb/sdk/interface/interface_shared.py", line 38, in _publish_output_raw
    self._publish(rec)
  File "/Users/lawrencebinding/miniconda3/envs/ML/lib/python3.9/site-packages/wandb/sdk/interface/interface_sock.py", line 39, in _publish
    self._sock_client.send_record_publish(record)
  File "/Users/lawrencebinding/miniconda3/envs/ML/lib/python3.9/site-packages/wandb/sdk/lib/sock_client.py", line 174, in send_record_publish
    self.send_server_request(server_req)
  File "/Users/lawrencebinding/miniconda3/envs/ML/lib/python3.9/site-packages/wandb/sdk/lib/sock_client.py", line 154, in send_server_request
    self._send_message(msg)
  File "/Users/lawrencebinding/miniconda3/envs/ML/lib/python3.9/site-packages/wandb/sdk/lib/sock_client.py", line 151, in _send_message
    self._sendall_with_error_handle(header + data)
  File "/Users/lawrencebinding/miniconda3/envs/ML/lib/python3.9/site-packages/wandb/sdk/lib/sock_client.py", line 130, in _sendall_with_error_handle
    sent = self._sock.send(data)
BrokenPipeError: [Errno 32] Broken pipe
